Workbook

Sheet 큐레이션마스터
A1: id | B1: 곡명 | C1: 아티스트 | D1: 연도 | E1: 무드 | F1: 순간 | G1: 그룹 | H1: videoId | I1: 유튜브URL | J1: 유튜브뮤직URL | K1: 썸네일URL | L1: 공식채널확인 | M1: 검증완료 | N1: 타겟적합(20-30) | O1: 비고 | P1: 유튜브 열기(자동) | Q1: 유튜브뮤직 열기(자동)
A2: S001 | B2: How Sweet | C2: NewJeans | D2: 2024 | E2: 상큼발랄 | F2: 바다, 드라이브 | G2: 여돌 | I2: =IF($H2="","","https://youtu.be/"&$H2) | J2: =IF($H2="","","https://music.youtube.com/watch?v="&$H2) | K2: =IF($H2="","","https://img.youtube.com/vi/"&$H2&"/hqdefault.jpg") | L2: 확인필요 | M2: N | N2: 높음 | O2: 씨앗(검증 전) | P2: https://www.youtube.com/results?search_query=NewJeans%20How%20Sweet | Q2: https://music.youtube.com/search?q=NewJeans%20How%20Sweet
A3: S002 | B3: Cake | C3: 있지 | D3: 2023 | E3: 상큼발랄 | F3: 바다 | G3: 여돌 | I3: =IF($H3="","","https://youtu.be/"&$H3) | J3: =IF($H3="","","https://music.youtube.com/watch?v="&$H3) | K3: =IF($H3="","","https://img.youtube.com/vi/"&$H3&"/hqdefault.jpg") | L3: 확인필요 | M3: N | N3: 높음 | O3: 씨앗(검증 전) | P3: https://www.youtube.com/results?search_query=%EC%9E%88%EC%A7%80%20Cake | Q3: https://music.youtube.com/search?q=%EC%9E%88%EC%A7%80%20Cake
A4: S003 | B4: Cupid | C4: 피프티 피프티 | D4: 2023 | E4: 상큼발랄 | F4: 바다 | G4: 여돌 | I4: =IF($H4="","","https://youtu.be/"&$H4) | J4: =IF($H4="","","https://music.youtube.com/watch?v="&$H4) | K4: =IF($H4="","","https://img.youtube.com/vi/"&$H4&"/hqdefault.jpg") | L4: 확인필요 | M4: N | N4: 높음 | O4: 씨앗(검증 전) | P4: https://www.youtube.com/results?search_query=%ED%94%BC%ED%94%84%ED%8B%B0%20%ED%94%BC%ED%94%84%ED%8B%B0%20Cupid | Q4: https://music.youtube.com/search?q=%ED%94%BC%ED%94%84%ED%8B%B0%20%ED%94%BC%ED%94%84%ED%8B%B0%20Cupid
A5: S004 | B5: Kitsch | C5: IVE | D5: 2023 | E5: 상큼발랄 | F5: 바다 | G5: 여돌 | I5: =IF($H5="","","https://youtu.be/"&$H5) | J5: =IF($H5="","","https://music.youtube.com/watch?v="&$H5) | K5: =IF($H5="","","https://img.youtube.com/vi/"&$H5&"/hqdefault.jpg") | L5: 확인필요 | M5: N | N5: 높음 | O5: 씨앗(검증 전) | P5: https://www.youtube.com/results?search_query=IVE%20Kitsch | Q5: https://music.youtube.com/search?q=IVE%20Kitsch
A6: S005 | B6: Queencard (퀸카) | C6: 여자아이들 | D6: 2023 | E6: 상큼발랄 | F6: 바다 | G6: 여돌 | I6: =IF($H6="","","https://youtu.be/"&$H6) | J6: =IF($H6="","","https://music.youtube.com/watch?v="&$H6) | K6: =IF($H6="","","https://img.youtube.com/vi/"&$H6&"/hqdefault.jpg") | L6: 확인필요 | M6: N | N6: 높음 | O6: 씨앗(검증 전) | P6: https://www.youtube.com/results?search_query=%EC%97%AC%EC%9E%90%EC%95%84%EC%9D%B4%EB%93%A4%20Queencard%20%28%ED%80%B8%EC%B9%B4%29 | Q6: https://music.youtube.com/search?q=%EC%97%AC%EC%9E%90%EC%95%84%EC%9D%B4%EB%93%A4%20Queencard%20%28%ED%80%B8%EC%B9%B4%29
A7: S006 | B7: Teddy Bear | C7: STAYC | D7: 2023 | E7: 상큼발랄 | F7: 바다, 드라이브 | G7: 여돌 | I7: =IF($H7="","","https://youtu.be/"&$H7) | J7: =IF($H7="","","https://music.youtube.com/watch?v="&$H7) | K7: =IF($H7="","","https://img.youtube.com/vi/"&$H7&"/hqdefault.jpg") | L7: 확인필요 | M7: N | N7: 높음 | O7: 씨앗(검증 전) | P7: https://www.youtube.com/results?search_query=STAYC%20Teddy%20Bear | Q7: https://music.youtube.com/search?q=STAYC%20Teddy%20Bear
A8: S007 | B8: We Fresh | C8: 케플러 | D8: 2023 | E8: 상큼발랄 | F8: 바다 | G8: 여돌 | I8: =IF($H8="","","https://youtu.be/"&$H8) | J8: =IF($H8="","","https://music.youtube.com/watch?v="&$H8) | K8: =IF($H8="","","https://img.youtube.com/vi/"&$H8&"/hqdefault.jpg") | L8: 확인필요 | M8: N | N8: 높음 | O8: 씨앗(검증 전) | P8: https://www.youtube.com/results?search_query=%EC%BC%80%ED%94%8C%EB%9F%AC%20We%20Fresh | Q8: https://music.youtube.com/search?q=%EC%BC%80%ED%94%8C%EB%9F%AC%20We%20Fresh
A9: S008 | B9: Birthday | C9: 레드벨벳 | D9: 2022 | E9: 상큼발랄 | F9: 바다 | G9: 여돌 | I9: =IF($H9="","","https://youtu.be/"&$H9) | J9: =IF($H9="","","https://music.youtube.com/watch?v="&$H9) | K9: =IF($H9="","","https://img.youtube.com/vi/"&$H9&"/hqdefault.jpg") | L9: 확인필요 | M9: N | N9: 높음 | O9: 씨앗(검증 전) | P9: https://www.youtube.com/results?search_query=%EB%A0%88%EB%93%9C%EB%B2%A8%EB%B2%B3%20Birthday | Q9: https://music.youtube.com/search?q=%EB%A0%88%EB%93%9C%EB%B2%A8%EB%B2%B3%20Birthday
A10: S009 | B10: Fanfare | C10: 트와이스 | D10: 2022 | E10: 상큼발랄 | F10: 바다, 드라이브 | G10: 여돌 | I10: =IF($H10="","","https://youtu.be/"&$H10) | J10: =IF($H10="","","https://music.youtube.com/watch?v="&$H10) | K10: =IF($H10="","","https://img.youtube.com/vi/"&$H10&"/hqdefault.jpg") | L10: 확인필요 | M10: N | N10: 높음 | O10: 씨앗(검증 전) | P10: https://www.youtube.com/results?search_query=%ED%8A%B8%EC%99%80%EC%9D%B4%EC%8A%A4%20Fanfare | Q10: https://music.youtube.com/search?q=%ED%8A%B8%EC%99%80%EC%9D%B4%EC%8A%A4%20Fanfare
A11: S010 | B11: Giddy | C11: 케플러 | D11: 2022 | E11: 상큼발랄 | F11: 바다, 드라이브 | G11: 여돌 | I11: =IF($H11="","","https://youtu.be/"&$H11) | J11: =IF($H11="","","https://music.youtube.com/watch?v="&$H11) | K11: =IF($H11="","","https://img.youtube.com/vi/"&$H11&"/hqdefault.jpg") | L11: 확인필요 | M11: N | N11: 높음 | O11: 씨앗(검증 전) | P11: https://www.youtube.com/results?search_query=%EC%BC%80%ED%94%8C%EB%9F%AC%20Giddy | Q11: https://music.youtube.com/search?q=%EC%BC%80%ED%94%8C%EB%9F%AC%20Giddy
A12: S011 | B12: Sneakers | C12: 있지 | D12: 2022 | E12: 상큼발랄 | F12: 바다, 드라이브 | G12: 여돌 | I12: =IF($H12="","","https://youtu.be/"&$H12) | J12: =IF($H12="","","https://music.youtube.com/watch?v="&$H12) | K12: =IF($H12="","","https://img.youtube.com/vi/"&$H12&"/hqdefault.jpg") | L12: 확인필요 | M12: N | N12: 높음 | O12: 씨앗(검증 전) | P12: https://www.youtube.com/results?search_query=%EC%9E%88%EC%A7%80%20Sneakers | Q12: https://music.youtube.com/search?q=%EC%9E%88%EC%A7%80%20Sneakers
A13: S012 | B13: Up! | C13: 케플러 | D13: 2022 | E13: 상큼발랄 | F13: 바다 | G13: 여돌 | I13: =IF($H13="","","https://youtu.be/"&$H13) | J13: =IF($H13="","","https://music.youtube.com/watch?v="&$H13) | K13: =IF($H13="","","https://img.youtube.com/vi/"&$H13&"/hqdefault.jpg") | L13: 확인필요 | M13: N | N13: 높음 | O13: 씨앗(검증 전) | P13: https://www.youtube.com/results?search_query=%EC%BC%80%ED%94%8C%EB%9F%AC%20Up%21 | Q13: https://music.youtube.com/search?q=%EC%BC%80%ED%94%8C%EB%9F%AC%20Up%21
... A49: S048 | B49: Electric Shock | C49: f(x) | D49: 2012 | E49: 상큼발랄 | F49: 바다 | G49: 여돌 | I49: =IF($H49="","","https://youtu.be/"&$H49) | J49: =IF($H49="","","https://music.youtube.com/watch?v="&$H49) | K49: =IF($H49="","","https://img.youtube.com/vi/"&$H49&"/hqdefault.jpg") | L49: 확인필요 | M49: N | N49: 높음 | O49: 씨앗(검증 전) | P49: https://www.youtube.com/results?search_query=f%28x%29%20Electric%20Shock | Q49: https://music.youtube.com/search?q=f%28x%29%20Electric%20Shock
A50: S049 | B50: CRAZY | C50: 르세라핌 | D50: 2024 | E50: 청량시원 | F50: 바다 | G50: 여돌 | I50: =IF($H55="","","https://youtu.be/"&$H55) | J50: =IF($H55="","","https://music.youtube.com/watch?v="&$H55) | K50: =IF($H55="","","https://img.youtube.com/vi/"&$H55&"/hqdefault.jpg") | L50: 확인필요 | M50: N | N50: 높음 | O50: 씨앗(검증 전) | P50: https://www.youtube.com/results?search_query=%EB%A5%B4%EC%84%B8%EB%9D%BC%ED%95%8C%20CRAZY | Q50: https://music.youtube.com/search?q=%EB%A5%B4%EC%84%B8%EB%9D%BC%ED%95%8C%20CRAZY
A51: S050 | B51: HEYA | C51: IVE | D51: 2024 | E51: 청량시원 | F51: 바다, 드라이브 | G51: 여돌 | I51: =IF($H56="","","https://youtu.be/"&$H56) | J51: =IF($H56="","","https://music.youtube.com/watch?v="&$H56) | K51: =IF($H56="","","https://img.youtube.com/vi/"&$H56&"/hqdefault.jpg") | L51: 확인필요 | M51: N | N51: 높음 | O51: 씨앗(검증 전) | P51: https://www.youtube.com/results?search_query=IVE%20HEYA | Q51: https://music.youtube.com/search?q=IVE%20HEYA
A52: S051 | B52: Super Lady | C52: 여자아이들 | D52: 2024 | E52: 청량시원 | F52: 바다, 드라이브 | G52: 여돌 | I52: =IF($H57="","","https://youtu.be/"&$H57) | J52: =IF($H57="","","https://music.youtube.com/watch?v="&$H57) | K52: =IF($H57="","","https://img.youtube.com/vi/"&$H57&"/hqdefault.jpg") | L52: 확인필요 | M52: N | N52: 높음 | O52: 씨앗(검증 전) | P52: https://www.youtube.com/results?search_query=%EC%97%AC%EC%9E%90%EC%95%84%EC%9D%B4%EB%93%A4%20Super%20Lady | Q52: https://music.youtube.com/search?q=%EC%97%AC%EC%9E%90%EC%95%84%EC%9D%B4%EB%93%A4%20Super%20Lady
A53: S052 | B53: Supernatural | C53: NewJeans | D53: 2024 | E53: 청량시원 | F53: 드라이브 | G53: 여돌 | I53: =IF($H58="","","https://youtu.be/"&$H58) | J53: =IF($H58="","","https://music.youtube.com/watch?v="&$H58) | K53: =IF($H58="","","https://img.youtube.com/vi/"&$H58&"/hqdefault.jpg") | L53: 확인필요 | M53: N | N53: 높음 | O53: 씨앗(검증 전) | P53: https://www.youtube.com/results?search_query=NewJeans%20Supernatural | Q53: https://music.youtube.com/search?q=NewJeans%20Supernatural
A54: S053 | B54: Supernova | C54: aespa | D54: 2024 | E54: 청량시원 | F54: 바다, 드라이브 | G54: 여돌 | I54: =IF($H59="","","https://youtu.be/"&$H59) | J54: =IF($H59="","","https://music.youtube.com/watch?v="&$H59) | K54: =IF($H59="","","https://img.youtube.com/vi/"&$H59&"/hqdefault.jpg") | L54: 확인필요 | M54: N | N54: 높음 | O54: 씨앗(검증 전) | P54: https://www.youtube.com/results?search_query=aespa%20Supernova | Q54: https://music.youtube.com/search?q=aespa%20Supernova
A55: S054 | B55: Whiplash | C55: aespa | D55: 2024 | E55: 청량시원 | F55: 바다 | G55: 여돌 | I55: =IF($H60="","","https://youtu.be/"&$H60) | J55: =IF($H60="","","https://music.youtube.com/watch?v="&$H60) | K55: =IF($H60="","","https://img.youtube.com/vi/"&$H60&"/hqdefault.jpg") | L55: 확인필요 | M55: N | N55: 높음 | O55: 씨앗(검증 전) | P55: https://www.youtube.com/results?search_query=aespa%20Whiplash | Q55: https://music.youtube.com/search?q=aespa%20Whiplash
A56: S055 | B56: 클락션 (Klaxon) | C56: 여자아이들 | D56: 2024 | E56: 청량시원 | F56: 드라이브 | G56: 여돌 | I56: =IF($H61="","","https://youtu.be/"&$H61) | J56: =IF($H61="","","https://music.youtube.com/watch?v="&$H61) | K56: =IF($H61="","","https://img.youtube.com/vi/"&$H61&"/hqdefault.jpg") | L56: 확인필요 | M56: N | N56: 높음 | O56: 씨앗(검증 전) | P56: https://www.youtube.com/results?search_query=%EC%97%AC%EC%9E%90%EC%95%84%EC%9D%B4%EB%93%A4%20%ED%81%B4%EB%9D%BD%EC%85%98%20%28Klaxon%29 | Q56: https://music.youtube.com/search?q=%EC%97%AC%EC%9E%90%EC%95%84%EC%9D%B4%EB%93%A4%20%ED%81%B4%EB%9D%BD%EC%85%98%20%28Klaxon%29
A57: S056 | B57: Baddie | C57: IVE | D57: 2023 | E57: 청량시원 | F57: 드라이브 | G57: 여돌 | I57: =IF($H62="","","https://youtu.be/"&$H62) | J57: =IF($H62="","","https://music.youtube.com/watch?v="&$H62) | K57: =IF($H62="","","https://img.youtube.com/vi/"&$H62&"/hqdefault.jpg") | L57: 확인필요 | M57: N | N57: 높음 | O57: 씨앗(검증 전) | P57: https://www.youtube.com/results?search_query=IVE%20Baddie | Q57: https://music.youtube.com/search?q=IVE%20Baddie
A58: S057 | B58: Beautiful Monster | C58: STAYC | D58: 2023 | E58: 청량시원 | F58: 바다 | G58: 여돌 | I58: =IF($H63="","","https://youtu.be/"&$H63) | J58: =IF($H63="","","https://music.youtube.com/watch?v="&$H63) | K58: =IF($H63="","","https://img.youtube.com/vi/"&$H63&"/hqdefault.jpg") | L58: 확인필요 | M58: N | N58: 높음 | O58: 씨앗(검증 전) | P58: https://www.youtube.com/results?search_query=STAYC%20Beautiful%20Monster | Q58: https://music.youtube.com/search?q=STAYC%20Beautiful%20Monster
A59: S058 | B59: Bubble | C59: STAYC | D59: 2023 | E59: 청량시원 | F59: 바다, 드라이브 | G59: 여돌 | I59: =IF($H64="","","https://youtu.be/"&$H64) | J59: =IF($H64="","","https://music.youtube.com/watch?v="&$H64) | K59: =IF($H64="","","https://img.youtube.com/vi/"&$H64&"/hqdefault.jpg") | L59: 확인필요 | M59: N | N59: 높음 | O59: 씨앗(검증 전) | P59: https://www.youtube.com/results?search_query=STAYC%20Bubble | Q59: https://music.youtube.com/search?q=STAYC%20Bubble
A60: S059 | B60: Drama | C60: aespa | D60: 2023 | E60: 청량시원 | F60: 드라이브 | G60: 여돌 | I60: =IF($H65="","","https://youtu.be/"&$H65) | J60: =IF($H65="","","https://music.youtube.com/watch?v="&$H65) | K60: =IF($H65="","","https://img.youtube.com/vi/"&$H65&"/hqdefault.jpg") | L60: 확인필요 | M60: N | N60: 높음 | O60: 씨앗(검증 전) | P60: https://www.youtube.com/results?search_query=aespa%20Drama | Q60: https://music.youtube.com/search?q=aespa%20Drama
A61: S060 | B61: ETA | C61: NewJeans | D61: 2023 | E61: 청량시원 | F61: 바다 | G61: 여돌 | I61: =IF($H66="","","https://youtu.be/"&$H66) | J61: =IF($H66="","","https://music.youtube.com/watch?v="&$H66) | K61: =IF($H66="","","https://img.youtube.com/vi/"&$H66&"/hqdefault.jpg") | L61: 확인필요 | M61: N | N61: 높음 | O61: 씨앗(검증 전) | P61: https://www.youtube.com/results?search_query=NewJeans%20ETA | Q61: https://music.youtube.com/search?q=NewJeans%20ETA
... A98: S097 | B98: 뛰어(Run) | C98: 여자아이들 | D98: 2018 | E98: 청량시원 | F98: 드라이브 | G98: 여돌 | I98: =IF($H103="","","https://youtu.be/"&$H103) | J98: =IF($H103="","","https://music.youtube.com/watch?v="&$H103) | K98: =IF($H103="","","https://img.youtube.com/vi/"&$H103&"/hqdefault.jpg") | L98: 확인필요 | M98: N | N98: 높음 | O98: 씨앗(검증 전) | P98: https://www.youtube.com/results?search_query=%EC%97%AC%EC%9E%90%EC%95%84%EC%9D%B4%EB%93%A4%20%EB%9B%B0%EC%96%B4%28Run%29 | Q98: https://music.youtube.com/search?q=%EC%97%AC%EC%9E%90%EC%95%84%EC%9D%B4%EB%93%A4%20%EB%9B%B0%EC%96%B4%28Run%29
A99: S098 | B99: As If It's Your Last (마지막처럼) | C99: 블랙핑크 | D99: 2017 | E99: 청량시원 | F99: 드라이브 | G99: 여돌 | I99: =IF($H105="","","https://youtu.be/"&$H105) | J99: =IF($H105="","","https://music.youtube.com/watch?v="&$H105) | K99: =IF($H105="","","https://img.youtube.com/vi/"&$H105&"/hqdefault.jpg") | L99: 확인필요 | M99: N | N99: 높음 | O99: 씨앗(검증 전) | P99: https://www.youtube.com/results?search_query=%EB%B8%94%EB%9E%99%ED%95%91%ED%81%AC%20As%20If%20It%27s%20Your%20Last%20%28%EB%A7%88%EC%A7%80%EB%A7%89%EC%B2%98%EB%9F%BC%29 | Q99: https://music.youtube.com/search?q=%EB%B8%94%EB%9E%99%ED%95%91%ED%81%AC%20As%20If%20It%27s%20Your%20Last%20%28%EB%A7%88%EC%A7%80%EB%A7%89%EC%B2%98%EB%9F%BC%29
A100: S099 | B100: 귀를 기울이면 (Love Whisper) | C100: 여자친구 | D100: 2017 | E100: 청량시원 | F100: 바다 | G100: 여돌 | I100: =IF($H106="","","https://youtu.be/"&$H106) | J100: =IF($H106="","","https://music.youtube.com/watch?v="&$H106) | K100: =IF($H106="","","https://img.youtube.com/vi/"&$H106&"/hqdefault.jpg") | L100: 확인필요 | M100: N | N100: 높음 | O100: 씨앗(검증 전) | P100: https://www.youtube.com/results?search_query=%EC%97%AC%EC%9E%90%EC%B9%9C%EA%B5%AC%20%EA%B7%80%EB%A5%BC%20%EA%B8%B0%EC%9A%B8%EC%9D%B4%EB%A9%B4%20%28Love%20Whisper%29 | Q100: https://music.youtube.com/search?q=%EC%97%AC%EC%9E%90%EC%B9%9C%EA%B5%AC%20%EA%B7%80%EB%A5%BC%20%EA%B8%B0%EC%9A%B8%EC%9D%B4%EB%A9%B4%20%28Love%20Whisper%29
A101: S100 | B101: 덜덜덜 (DDD) | C101: EXID | D101: 2017 | E101: 청량시원 | F101: 바다, 드라이브 | G101: 여돌 | I101: =IF($H107="","","https://youtu.be/"&$H107) | J101: =IF($H107="","","https://music.youtube.com/watch?v="&$H107) | K101: =IF($H107="","","https://img.youtube.com/vi/"&$H107&"/hqdefault.jpg") | L101: 확인필요 | M101: N | N101: 높음 | O101: 씨앗(검증 전) | P101: https://www.youtube.com/results?search_query=EXID%20%EB%8D%9C%EB%8D%9C%EB%8D%9C%20%28DDD%29 | Q101: https://music.youtube.com/search?q=EXID%20%EB%8D%9C%EB%8D%9C%EB%8D%9C%20%28DDD%29
A102: S101 | B102: Why So Lonely | C102: 원더걸스 | D102: 2016 | E102: 청량시원 | F102: 드라이브 | G102: 여돌 | I102: =IF($H110="","","https://youtu.be/"&$H110) | J102: =IF($H110="","","https://music.youtube.com/watch?v="&$H110) | K102: =IF($H110="","","https://img.youtube.com/vi/"&$H110&"/hqdefault.jpg") | L102: 확인필요 | M102: N | N102: 높음 | O102: 씨앗(검증 전) | P102: https://www.youtube.com/results?search_query=%EC%9B%90%EB%8D%94%EA%B1%B8%EC%8A%A4%20Why%20So%20Lonely | Q102: https://music.youtube.com/search?q=%EC%9B%90%EB%8D%94%EA%B1%B8%EC%8A%A4%20Why%20So%20Lonely
A103: S102 | B103: Windy Day | C103: 오마이걸 | D103: 2016 | E103: 청량시원 | F103: 바다, 드라이브 | G103: 여돌 | I103: =IF($H111="","","https://youtu.be/"&$H111) | J103: =IF($H111="","","https://music.youtube.com/watch?v="&$H111) | K103: =IF($H111="","","https://img.youtube.com/vi/"&$H111&"/hqdefault.jpg") | L103: 확인필요 | M103: N | N103: 높음 | O103: 씨앗(검증 전) | P103: https://www.youtube.com/results?search_query=%EC%98%A4%EB%A7%88%EC%9D%B4%EA%B1%B8%20Windy%20Day | Q103: https://music.youtube.com/search?q=%EC%98%A4%EB%A7%88%EC%9D%B4%EA%B1%B8%20Windy%20Day
A104: S103 | B104: 너 그리고 나 (NAVILLERA) | C104: 여자친구 | D104: 2016 | E104: 청량시원 | F104: 바다, 드라이브 | G104: 여돌 | I104: =IF($H112="","","https://youtu.be/"&$H112) | J104: =IF($H112="","","https://music.youtube.com/watch?v="&$H112) | K104: =IF($H112="","","https://img.youtube.com/vi/"&$H112&"/hqdefault.jpg") | L104: 확인필요 | M104: N | N104: 높음 | O104: 씨앗(검증 전) | P104: https://www.youtube.com/results?search_query=%EC%97%AC%EC%9E%90%EC%B9%9C%EA%B5%AC%20%EB%84%88%20%EA%B7%B8%EB%A6%AC%EA%B3%A0%20%EB%82%98%20%28NAVILLERA%29 | Q104: https://music.youtube.com/search?q=%EC%97%AC%EC%9E%90%EC%B9%9C%EA%B5%AC%20%EB%84%88%20%EA%B7%B8%EB%A6%AC%EA%B3%A0%20%EB%82%98%20%28NAVILLERA%29
A105: S104 | B105: 싫어 (Hate) | C105: 포미닛 | D105: 2016 | E105: 청량시원 | F105: 바다, 드라이브 | G105: 여돌 | I105: =IF($H113="","","https://youtu.be/"&$H113) | J105: =IF($H113="","","https://music.youtube.com/watch?v="&$H113) | K105: =IF($H113="","","https://img.youtube.com/vi/"&$H113&"/hqdefault.jpg") | L105: 확인필요 | M105: N | N105: 높음 | O105: 씨앗(검증 전) | P105: https://www.youtube.com/results?search_query=%ED%8F%AC%EB%AF%B8%EB%8B%9B%20%EC%8B%AB%EC%96%B4%20%28Hate%29 | Q105: https://music.youtube.com/search?q=%ED%8F%AC%EB%AF%B8%EB%8B%9B%20%EC%8B%AB%EC%96%B4%20%28Hate%29
A106: S105 | B106: I Swear | C106: 씨스타 | D106: 2014 | E106: 청량시원 | F106: 바다, 드라이브 | G106: 여돌 | I106: =IF($H119="","","https://youtu.be/"&$H119) | J106: =IF($H119="","","https://music.youtube.com/watch?v="&$H119) | K106: =IF($H119="","","https://img.youtube.com/vi/"&$H119&"/hqdefault.jpg") | L106: 확인필요 | M106: N | N106: 높음 | O106: 씨앗(검증 전) | P106: https://www.youtube.com/results?search_query=%EC%94%A8%EC%8A%A4%ED%83%80%20I%20Swear | Q106: https://music.youtube.com/search?q=%EC%94%A8%EC%8A%A4%ED%83%80%20I%20Swear
A107: S106 | B107: Mr.Mr. | C107: 소녀시대 | D107: 2014 | E107: 청량시원 | F107: 바다, 드라이브 | G107: 여돌 | I107: =IF($H120="","","https://youtu.be/"&$H120) | J107: =IF($H120="","","https://music.youtube.com/watch?v="&$H120) | K107: =IF($H120="","","https://img.youtube.com/vi/"&$H120&"/hqdefault.jpg") | L107: 확인필요 | M107: N | N107: 높음 | O107: 씨앗(검증 전) | P107: https://www.youtube.com/results?search_query=%EC%86%8C%EB%85%80%EC%8B%9C%EB%8C%80%20Mr.Mr. | Q107: https://music.youtube.com/search?q=%EC%86%8C%EB%85%80%EC%8B%9C%EB%8C%80%20Mr.Mr.
A108: S107 | B108: Touch My Body | C108: 씨스타 | D108: 2014 | E108: 청량시원 | F108: 드라이브 | G108: 여돌 | I108: =IF($H121="","","https://youtu.be/"&$H121) | J108: =IF($H121="","","https://music.youtube.com/watch?v="&$H121) | K108: =IF($H121="","","https://img.youtube.com/vi/"&$H121&"/hqdefault.jpg") | L108: 확인필요 | M108: N | N108: 높음 | O108: 씨앗(검증 전) | P108: https://www.youtube.com/results?search_query=%EC%94%A8%EC%8A%A4%ED%83%80%20Touch%20My%20Body | Q108: https://music.youtube.com/search?q=%EC%94%A8%EC%8A%A4%ED%83%80%20Touch%20My%20Body
A109: S108 | B109: 좋아요 (Like a Cat) | C109: AOA | D109: 2014 | E109: 청량시원 | F109: 바다, 드라이브 | G109: 여돌 | I109: =IF($H122="","","https://youtu.be/"&$H122) | J109: =IF($H122="","","https://music.youtube.com/watch?v="&$H122) | K109: =IF($H122="","","https://img.youtube.com/vi/"&$H122&"/hqdefault.jpg") | L109: 확인필요 | M109: N | N109: 높음 | O109: 씨앗(검증 전) | P109: https://www.youtube.com/results?search_query=AOA%20%EC%A2%8B%EC%95%84%EC%9A%94%20%28Like%20a%20Cat%29 | Q109: https://music.youtube.com/search?q=AOA%20%EC%A2%8B%EC%95%84%EC%9A%94%20%28Like%20a%20Cat%29
A110: S109 | B110: 기대해 (Expect) | C110: 걸스데이 | D110: 2013 | E110: 청량시원 | F110: 바다 | G110: 여돌 | I110: =IF($H123="","","https://youtu.be/"&$H123) | J110: =IF($H123="","","https://music.youtube.com/watch?v="&$H123) | K110: =IF($H123="","","https://img.youtube.com/vi/"&$H123&"/hqdefault.jpg") | L110: 확인필요 | M110: N | N110: 높음 | O110: 씨앗(검증 전) | P110: https://www.youtube.com/results?search_query=%EA%B1%B8%EC%8A%A4%EB%8D%B0%EC%9D%B4%20%EA%B8%B0%EB%8C%80%ED%95%B4%20%28Expect%29 | Q110: https://music.youtube.com/search?q=%EA%B1%B8%EC%8A%A4%EB%8D%B0%EC%9D%B4%20%EA%B8%B0%EB%8C%80%ED%95%B4%20%28Expect%29
A111: S110 | B111: Loving U (러빙유) | C111: 씨스타 | D111: 2012 | E111: 청량시원 | F111: 바다 | G111: 여돌 | I111: =IF($H124="","","https://youtu.be/"&$H124) | J111: =IF($H124="","","https://music.youtube.com/watch?v="&$H124) | K111: =IF($H124="","","https://img.youtube.com/vi/"&$H124&"/hqdefault.jpg") | L111: 확인필요 | M111: N | N111: 높음 | O111: 씨앗(검증 전) | P111: https://www.youtube.com/results?search_query=%EC%94%A8%EC%8A%A4%ED%83%80%20Loving%20U%20%28%EB%9F%AC%EB%B9%99%EC%9C%A0%29 | Q111: https://music.youtube.com/search?q=%EC%94%A8%EC%8A%A4%ED%83%80%20Loving%20U%20%28%EB%9F%AC%EB%B9%99%EC%9C%A0%29
...

Sheet 집계
A1: 카테고리별 집계 (자동 계산)
A2: 총 곡수 | B2: =COUNTA(큐레이션마스터!A2:A512)
A4: 무드
A5: 항목 | B5: 곡수
A6: 상큼발랄 | B6: =COUNTIF(큐레이션마스터!$E$2:$E$512,"상큼발랄")
A7: 청량시원 | B7: =COUNTIF(큐레이션마스터!$E$2:$E$512,"청량시원")
A8: 설렘두근 | B8: =COUNTIF(큐레이션마스터!$E$2:$E$512,"설렘두근")
A9: 센치감성 | B9: =COUNTIF(큐레이션마스터!$E$2:$E$512,"센치감성")
A11: 순간
A12: 항목 | B12: 곡수
A13: 바다 | B13: =COUNTIF(큐레이션마스터!$F$2:$F$512,"*바다*")-COUNTIF(큐레이션마스터!$F$2:$F$512,"*밤바다*")
A14: 드라이브 | B14: =COUNTIF(큐레이션마스터!$F$2:$F$512,"*드라이브*")
A15: 밤바다 | B15: =COUNTIF(큐레이션마스터!$F$2:$F$512,"*밤바다*")
A16: 비오는날 | B16: =COUNTIF(큐레이션마스터!$F$2:$F$512,"*비오는날*")
A18: 그룹
A19: 항목 | B19: 곡수
A20: 여돌 | B20: =COUNTIF(큐레이션마스터!$G$2:$G$512,"여돌")
A21: 남돌 | B21: =COUNTIF(큐레이션마스터!$G$2:$G$512,"남돌")
A22: 솔로 | B22: =COUNTIF(큐레이션마스터!$G$2:$G$512,"솔로")
A23: 밴드 | B23: =COUNTIF(큐레이션마스터!$G$2:$G$512,"밴드")
A24: 그룹 | B24: =COUNTIF(큐레이션마스터!$G$2:$G$512,"그룹")
A25: 힙합 | B25: =COUNTIF(큐레이션마스터!$G$2:$G$512,"힙합")
A26: 기타 | B26: =COUNTIF(큐레이션마스터!$G$2:$G$512,"기타")

Sheet 카테고리정의
A1: 카테고리 체계 (3축) · 메인 타겟 20~30대 · 2010년 이후 곡만
A3: 축 | B3: 값 | C3: 비고
A4: 무드(감정,1개) | B4: 상큼발랄 / 청량시원 / 설렘두근 / 센치감성 | C4: 곡당 1개
A5: 순간(상황,다중) | B5: 바다 / 드라이브 / 밤바다 / 비오는날 | C5: 무드 기반 재분배로 균형화
A6: 아티스트(그룹) | B6: 여돌 / 남돌 / 솔로 / 밴드 / 그룹 / 힙합 / 기타 | C6: 여돌=상큼, 남돌=청량 강조

Sheet 가이드
A1: 사용 가이드
A3: 1) videoId(11자리)만 넣으면 유튜브/유튜브뮤직/썸네일 URL 자동 생성.
A4: 2) 전 곡 2010년 이후, 봄/가을/겨울 곡 제외. 그룹→무드→연도순 정렬.
A5: 3) 순간 태그는 무드 기반으로 재분배해 4개 카테고리를 균형화(검증 시 곡별로 미세조정 가능).
A6: 4) 대부분 '검증 전' 씨앗 → 공식 영상·연도 확인 후 검증완료=Y.
A7: 5) videoId는 비오는날 10곡만 확보(참조 아티클) → 공식 채널 재확인 필요.
A8: 6) 집계 시트에서 무드/순간/그룹 곡수 자동 확인. 상단 필터로 즉시 플레이리스트 추출.
A9: 7) 출처: 여자아이돌·밴드/인디=웹 리서치, 남자아이돌·힙합/시즌송=큐레이션 지식(연도 검증 권장).
A11: [열기(자동) 컬럼 안내]
A12: · P/Q '유튜브 열기(자동)/유튜브뮤직 열기(자동)'은 모든 곡에서 즉시 동작하는 링크입니다.
A13: - videoId가 있으면 해당 영상 직접 재생, 없으면 '아티스트 곡명' 검색 결과로 열림(대개 최상단이 공식).
A14: - 앱의 openURL에 이 컬럼을 넣으면 300곡 전부 바로 재생 가능(검증 불필요).
... A16: · videoId 대량 확보는 유튜브 데이터 API 키로 스크립트 채우기 권장(검색 100유닛/건, 무료쿼터 하루 약 100건).
